Process A [NEW] (arrival time 9 ms) 16 CPU bursts
Process B [NEW] (arrival time 18 ms) 21 CPU bursts
Process C [NEW] (arrival time 42 ms) 4 CPU bursts
Process D [NEW] (arrival time 156 ms) 11 CPU bursts
Process E [NEW] (arrival time 134 ms) 55 CPU bursts
Process F [NEW] (arrival time 106 ms) 34 CPU bursts
Process G [NEW] (arrival time 65 ms) 80 CPU bursts
Process H [NEW] (arrival time 11 ms) 83 CPU bursts
Process I [NEW] (arrival time 68 ms) 77 CPU bursts
Process J [NEW] (arrival time 0 ms) 10 CPU bursts
Process K [NEW] (arrival time 7 ms) 13 CPU bursts
Process L [NEW] (arrival time 189 ms) 7 CPU bursts
Process M [NEW] (arrival time 16 ms) 48 CPU bursts
Process N [NEW] (arrival time 122 ms) 31 CPU bursts
Process O [NEW] (arrival time 29 ms) 31 CPU bursts
Process P [NEW] (arrival time 159 ms) 16 CPU bursts
time 0ms: Simulator started for FCFS [Q <empty>]
time 0ms: Process J arrived; added to ready queue [Q J]
time 2ms: Process J started using the CPU for 40ms burst [Q <empty>]
time 7ms: Process K arrived; added to ready queue [Q K]
time 9ms: Process A arrived; added to ready queue [Q K A]
time 11ms: Process H arrived; added to ready queue [Q K A H]
time 16ms: Process M arrived; added to ready queue [Q K A H M]
time 18ms: Process B arrived; added to ready queue [Q K A H M B]
time 29ms: Process O arrived; added to ready queue [Q K A H M B O]
time 42ms: Process J completed a CPU burst; 9 bursts to go [Q K A H M B O]
time 42ms: Process J switching out of CPU; will block on I/O until time 47ms [Q K A H M B O]
time 42ms: Process C arrived; added to ready queue [Q K A H M B O C]
time 46ms: Process K started using the CPU for 64ms burst [Q A H M B O C]
time 47ms: Process J completed I/O; added to ready queue [Q A H M B O C J]
time 65ms: Process G arrived; added to ready queue [Q A H M B O C J G]
time 68ms: Process I arrived; added to ready queue [Q A H M B O C J G I]
time 106ms: Process F arrived; added to ready queue [Q A H M B O C J G I F]
time 110ms: Process K completed a CPU burst; 12 bursts to go [Q A H M B O C J G I F]
time 110ms: Process K switching out of CPU; will block on I/O until time 208ms [Q A H M B O C J G I F]
time 114ms: Process A started using the CPU for 56ms burst [Q H M B O C J G I F]
time 122ms: Process N arrived; added to ready queue [Q H M B O C J G I F N]
time 134ms: Process E arrived; added to ready queue [Q H M B O C J G I F N E]
time 156ms: Process D arrived; added to ready queue [Q H M B O C J G I F N E D]
time 159ms: Process P arrived; added to ready queue [Q H M B O C J G I F N E D P]
time 170ms: Process A completed a CPU burst; 15 bursts to go [Q H M B O C J G I F N E D P]
time 170ms: Process A switching out of CPU; will block on I/O until time 195ms [Q H M B O C J G I F N E D P]
time 174ms: Process H started using the CPU for 96ms burst [Q M B O C J G I F N E D P]
time 189ms: Process L arrived; added to ready queue [Q M B O C J G I F N E D P L]
time 195ms: Process A completed I/O; added to ready queue [Q M B O C J G I F N E D P L A]
time 208ms: Process K completed I/O; added to ready queue [Q M B O C J G I F N E D P L A K]
time 270ms: Process H completed a CPU burst; 82 bursts to go [Q M B O C J G I F N E D P L A K]
time 270ms: Process H switching out of CPU; will block on I/O until time 339ms [Q M B O C J G I F N E D P L A K]
time 274ms: Process M started using the CPU for 22ms burst [Q B O C J G I F N E D P L A K]
time 296ms: Process M completed a CPU burst; 47 bursts to go [Q B O C J G I F N E D P L A K]
time 296ms: Process M switching out of CPU; will block on I/O until time 315ms [Q B O C J G I F N E D P L A K]
time 300ms: Process B started using the CPU for 106ms burst [Q O C J G I F N E D P L A K]
time 315ms: Process M completed I/O; added to ready queue [Q O C J G I F N E D P L A K M]
time 339ms: Process H completed I/O; added to ready queue [Q O C J G I F N E D P L A K M H]
time 406ms: Process B completed a CPU burst; 20 bursts to go [Q O C J G I F N E D P L A K M H]
time 406ms: Process B switching out of CPU; will block on I/O until time 564ms [Q O C J G I F N E D P L A K M H]
time 410ms: Process O started using the CPU for 156ms burst [Q C J G I F N E D P L A K M H]
time 564ms: Process B completed I/O; added to ready queue [Q C J G I F N E D P L A K M H B]
time 566ms: Process O completed a CPU burst; 30 bursts to go [Q C J G I F N E D P L A K M H B]
time 566ms: Process O switching out of CPU; will block on I/O until time 635ms [Q C J G I F N E D P L A K M H B]
time 570ms: Process C started using the CPU for 94ms burst [Q J G I F N E D P L A K M H B]
time 635ms: Process O completed I/O; added to ready queue [Q J G I F N E D P L A K M H B O]
time 664ms: Process C completed a CPU burst; 3 bursts to go [Q J G I F N E D P L A K M H B O]
time 664ms: Process C switching out of CPU; will block on I/O until time 824ms [Q J G I F N E D P L A K M H B O]
time 668ms: Process J started using the CPU for 204ms burst [Q G I F N E D P L A K M H B O]
time 824ms: Process C completed I/O; added to ready queue [Q G I F N E D P L A K M H B O C]
time 872ms: Process J completed a CPU burst; 8 bursts to go [Q G I F N E D P L A K M H B O C]
time 872ms: Process J switching out of CPU; will block on I/O until time 944ms [Q G I F N E D P L A K M H B O C]
time 876ms: Process G started using the CPU for 70ms burst [Q I F N E D P L A K M H B O C]
time 944ms: Process J completed I/O; added to ready queue [Q I F N E D P L A K M H B O C J]
time 946ms: Process G completed a CPU burst; 79 bursts to go [Q I F N E D P L A K M H B O C J]
time 946ms: Process G switching out of CPU; will block on I/O until time 979ms [Q I F N E D P L A K M H B O C J]
time 950ms: Process I started using the CPU for 220ms burst [Q F N E D P L A K M H B O C J]
time 979ms: Process G completed I/O; added to ready queue [Q F N E D P L A K M H B O C J G]
time 4634ms: Process C terminated [Q B J G O F E I N K L A D H P]
time 8845ms: Process L terminated [Q A K D B H M J P F E G N O I]
time 10611ms: Process J terminated [Q P F E G N O K D A I B H]
time 13604ms: Process D terminated [Q K A O B I M H F E G]
time 14739ms: Process K terminated [Q A I B M H O F G E]
time 17915ms: Process A terminated [Q I B M F O G N P E H]
time 19250ms: Process P terminated [Q E H I B F O M]
time 21901ms: Process B terminated [Q M O H E F G N I]
time 29646ms: Process O terminated [Q N I F M]
time 29716ms: Process N terminated [Q I F M H G]
time 31078ms: Process F terminated [Q I H M G E]
time 37417ms: Process M terminated [Q E G H]
time 39678ms: Process E terminated [Q H G I]
time 46801ms: Process I terminated [Q <empty>]
time 47484ms: Process G terminated [Q <empty>]
time 47921ms: Process H terminated [Q <empty>]
time 47923ms: Simulator ended for FCFS [Q <empty>]

Process A [NEW] (arrival time 9 ms) 16 CPU bursts (tau 100ms)
Process B [NEW] (arrival time 18 ms) 21 CPU bursts (tau 100ms)
Process C [NEW] (arrival time 42 ms) 4 CPU bursts (tau 100ms)
Process D [NEW] (arrival time 156 ms) 11 CPU bursts (tau 100ms)
Process E [NEW] (arrival time 134 ms) 55 CPU bursts (tau 100ms)
Process F [NEW] (arrival time 106 ms) 34 CPU bursts (tau 100ms)
Process G [NEW] (arrival time 65 ms) 80 CPU bursts (tau 100ms)
Process H [NEW] (arrival time 11 ms) 83 CPU bursts (tau 100ms)
Process I [NEW] (arrival time 68 ms) 77 CPU bursts (tau 100ms)
Process J [NEW] (arrival time 0 ms) 10 CPU bursts (tau 100ms)
Process K [NEW] (arrival time 7 ms) 13 CPU bursts (tau 100ms)
Process L [NEW] (arrival time 189 ms) 7 CPU bursts (tau 100ms)
Process M [NEW] (arrival time 16 ms) 48 CPU bursts (tau 100ms)
Process N [NEW] (arrival time 122 ms) 31 CPU bursts (tau 100ms)
Process O [NEW] (arrival time 29 ms) 31 CPU bursts (tau 100ms)
Process P [NEW] (arrival time 159 ms) 16 CPU bursts (tau 100ms)
time 0ms: Simulator started for SJF [Q <empty>]
time 0ms: Process J (tau 100ms) arrived; added to ready queue [Q J]
time 2ms: Process J (tau 100ms) started using the CPU for 40ms burst [Q <empty>]
time 7ms: Process K (tau 100ms) arrived; added to ready queue [Q K]
time 9ms: Process A (tau 100ms) arrived; added to ready queue [Q A K]
time 11ms: Process H (tau 100ms) arrived; added to ready queue [Q A H K]
time 16ms: Process M (tau 100ms) arrived; added to ready queue [Q A H K M]
time 18ms: Process B (tau 100ms) arrived; added to ready queue [Q A B H K M]
time 29ms: Process O (tau 100ms) arrived; added to ready queue [Q A B H K M O]
time 42ms: Process J (tau 100ms) completed a CPU burst; 9 bursts to go [Q A B H K M O]
time 42ms: Recalculated tau = 55ms for process J [Q A B H K M O]
time 42ms: Process J switching out of CPU; will block on I/O until time 47ms [Q A B H K M O]
time 42ms: Process C (tau 100ms) arrived; added to ready queue [Q A B C H K M O]
time 46ms: Process A (tau 100ms) started using the CPU for 56ms burst [Q B C H K M O]
time 47ms: Process J (tau 55ms) completed I/O; added to ready queue [Q J B C H K M O]
time 65ms: Process G (tau 100ms) arrived; added to ready queue [Q J B C G H K M O]
time 68ms: Process I (tau 100ms) arrived; added to ready queue [Q J B C G H I K M O]
time 102ms: Process A (tau 100ms) completed a CPU burst; 15 bursts to go [Q J B C G H I K M O]
time 102ms: Recalculated tau = 67ms for process A [Q J B C G H I K M O]
time 102ms: Process A switching out of CPU; will block on I/O until time 127ms [Q J B C G H I K M O]
time 106ms: Process J (tau 55ms) started using the CPU for 204ms burst [Q B C G H I K M O]
time 106ms: Process F (tau 100ms) arrived; added to ready queue [Q B C F G H I K M O]
time 122ms: Process N (tau 100ms) arrived; added to ready queue [Q B C F G H I K M N O]
time 127ms: Process A (tau 67ms) completed I/O; added to ready queue [Q A B C F G H I K M N O]
time 134ms: Process E (tau 100ms) arrived; added to ready queue [Q A B C E F G H I K M N O]
time 156ms: Process D (tau 100ms) arrived; added to ready queue [Q A B C D E F G H I K M N O]
time 159ms: Process P (tau 100ms) arrived; added to ready queue [Q A B C D E F G H I K M N O P]
time 189ms: Process L (tau 100ms) arrived; added to ready queue [Q A B C D E F G H I K L M N O P]
time 310ms: Process J (tau 55ms) completed a CPU burst; 8 bursts to go [Q A B C D E F G H I K L M N O P]
time 310ms: Recalculated tau = 167ms for process J [Q A B C D E F G H I K L M N O P]
time 310ms: Process J switching out of CPU; will block on I/O until time 382ms [Q A B C D E F G H I K L M N O P]
time 314ms: Process A (tau 67ms) started using the CPU for 60ms burst [Q B C D E F G H I K L M N O P]
time 374ms: Process A (tau 67ms) completed a CPU burst; 14 bursts to go [Q B C D E F G H I K L M N O P]
time 374ms: Recalculated tau = 62ms for process A [Q B C D E F G H I K L M N O P]
time 374ms: Process A switching out of CPU; will block on I/O until time 529ms [Q B C D E F G H I K L M N O P]
time 378ms: Process B (tau 100ms) started using the CPU for 106ms burst [Q C D E F G H I K L M N O P]
time 382ms: Process J (tau 167ms) completed I/O; added to ready queue [Q C D E F G H I K L M N O P J]
time 484ms: Process B (tau 100ms) completed a CPU burst; 20 bursts to go [Q C D E F G H I K L M N O P J]
time 484ms: Recalculated tau = 105ms for process B [Q C D E F G H I K L M N O P J]
time 484ms: Process B switching out of CPU; will block on I/O until time 642ms [Q C D E F G H I K L M N O P J]
time 488ms: Process C (tau 100ms) started using the CPU for 94ms burst [Q D E F G H I K L M N O P J]
time 529ms: Process A (tau 62ms) completed I/O; added to ready queue [Q A D E F G H I K L M N O P J]
time 582ms: Process C (tau 100ms) completed a CPU burst; 3 bursts to go [Q A D E F G H I K L M N O P J]
time 582ms: Recalculated tau = 96ms for process C [Q A D E F G H I K L M N O P J]
time 582ms: Process C switching out of CPU; will block on I/O until time 742ms [Q A D E F G H I K L M N O P J]
time 586ms: Process A (tau 62ms) started using the CPU for 39ms burst [Q D E F G H I K L M N O P J]
time 625ms: Process A (tau 62ms) completed a CPU burst; 13 bursts to go [Q D E F G H I K L M N O P J]
time 625ms: Recalculated tau = 45ms for process A [Q D E F G H I K L M N O P J]
time 625ms: Process A switching out of CPU; will block on I/O until time 677ms [Q D E F G H I K L M N O P J]
time 629ms: Process D (tau 100ms) started using the CPU for 148ms burst [Q E F G H I K L M N O P J]
time 642ms: Process B (tau 105ms) completed I/O; added to ready queue [Q E F G H I K L M N O P B J]
time 677ms: Process A (tau 45ms) completed I/O; added to ready queue [Q A E F G H I K L M N O P B J]
time 742ms: Process C (tau 96ms) completed I/O; added to ready queue [Q A C E F G H I K L M N O P B J]
time 777ms: Process D (tau 100ms) completed a CPU burst; 10 bursts to go [Q A C E F G H I K L M N O P B J]
time 777ms: Recalculated tau = 136ms for process D [Q A C E F G H I K L M N O P B J]
time 777ms: Process D switching out of CPU; will block on I/O until time 781ms [Q A C E F G H I K L M N O P B J]
time 781ms: Process A (tau 45ms) started using the CPU for 47ms burst [Q C E F G H I K L M N O P B J]
time 781ms: Process D (tau 136ms) completed I/O; added to ready queue [Q C E F G H I K L M N O P B D J]
time 828ms: Process A (tau 45ms) completed a CPU burst; 12 bursts to go [Q C E F G H I K L M N O P B D J]
time 828ms: Recalculated tau = 47ms for process A [Q C E F G H I K L M N O P B D J]
time 828ms: Process A switching out of CPU; will block on I/O until time 832ms [Q C E F G H I K L M N O P B D J]
time 832ms: Process C (tau 96ms) started using the CPU for 117ms burst [Q E F G H I K L M N O P B D J]
time 832ms: Process A (tau 47ms) completed I/O; added to ready queue [Q A E F G H I K L M N O P B D J]
time 949ms: Process C (tau 96ms) completed a CPU burst; 2 bursts to go [Q A E F G H I K L M N O P B D J]
time 949ms: Recalculated tau = 112ms for process C [Q A E F G H I K L M N O P B D J]
time 949ms: Process C switching out of CPU; will block on I/O until time 968ms [Q A E F G H I K L M N O P B D J]
time 953ms: Process A (tau 47ms) started using the CPU for 137ms burst [Q E F G H I K L M N O P B D J]
time 968ms: Process C (tau 112ms) completed I/O; added to ready queue [Q E F G H I K L M N O P B C D J]
time 4754ms: Process C terminated [Q G A K F L H P D E O M J B N I]
time 7612ms: Process L terminated [Q A D H E O M G F J K B N I]
time 9505ms: Process A terminated [Q F E G O J H P K B N M I D]
time 14771ms: Process J terminated [Q E K B P F N M I D H]
time 14840ms: Process K terminated [Q E B P F N M I D H]
time 17271ms: Process P terminated [Q G F N M I D B H E]
time 22615ms: Process D terminated [Q F M N B O H E]
time 26736ms: Process F terminated [Q N B O H E G]
time 29276ms: Process O terminated [Q I B H N E G]
time 36897ms: Process M terminated [Q H N B E G]
time 37224ms: Process N terminated [Q B E G]
time 38477ms: Process B terminated [Q E H G I]
time 44410ms: Process G terminated [Q H I]
time 47198ms: Process E terminated [Q I H]
time 47251ms: Process I terminated [Q H]
time 47649ms: Process H terminated [Q <empty>]
time 47651ms: Simulator ended for SJF [Q <empty>]

Process A [NEW] (arrival time 9 ms) 16 CPU bursts (tau 100ms)
Process B [NEW] (arrival time 18 ms) 21 CPU bursts (tau 100ms)
Process C [NEW] (arrival time 42 ms) 4 CPU bursts (tau 100ms)
Process D [NEW] (arrival time 156 ms) 11 CPU bursts (tau 100ms)
Process E [NEW] (arrival time 134 ms) 55 CPU bursts (tau 100ms)
Process F [NEW] (arrival time 106 ms) 34 CPU bursts (tau 100ms)
Process G [NEW] (arrival time 65 ms) 80 CPU bursts (tau 100ms)
Process H [NEW] (arrival time 11 ms) 83 CPU bursts (tau 100ms)
Process I [NEW] (arrival time 68 ms) 77 CPU bursts (tau 100ms)
Process J [NEW] (arrival time 0 ms) 10 CPU bursts (tau 100ms)
Process K [NEW] (arrival time 7 ms) 13 CPU bursts (tau 100ms)
Process L [NEW] (arrival time 189 ms) 7 CPU bursts (tau 100ms)
Process M [NEW] (arrival time 16 ms) 48 CPU bursts (tau 100ms)
Process N [NEW] (arrival time 122 ms) 31 CPU bursts (tau 100ms)
Process O [NEW] (arrival time 29 ms) 31 CPU bursts (tau 100ms)
Process P [NEW] (arrival time 159 ms) 16 CPU bursts (tau 100ms)
time 0ms: Simulator started for SRT [Q <empty>]
time 0ms: Process J (tau 100ms) arrived; added to ready queue [Q J]
time 2ms: Process J (tau 100ms) started using the CPU with 40ms burst remaining [Q <empty>]
time 7ms: Process K (tau 100ms) arrived; added to ready queue [Q K]
time 9ms: Process A (tau 100ms) arrived; added to ready queue [Q A K]
time 11ms: Process H (tau 100ms) arrived; added to ready queue [Q A H K]
time 16ms: Process M (tau 100ms) arrived; added to ready queue [Q A H K M]
time 18ms: Process B (tau 100ms) arrived; added to ready queue [Q A B H K M]
time 29ms: Process O (tau 100ms) arrived; added to ready queue [Q A B H K M O]
time 42ms: Process J (tau 100ms) completed a CPU burst; 9 bursts to go [Q A B H K M O]
time 42ms: Recalculated tau = 55ms for process J [Q A B H K M O]
time 42ms: Process J switching out of CPU; will block on I/O until time 47ms [Q A B H K M O]
time 42ms: Process C (tau 100ms) arrived; added to ready queue [Q A B C H K M O]
time 46ms: Process A (tau 100ms) started using the CPU with 56ms burst remaining [Q B C H K M O]
time 47ms: Process J (tau 55ms) completed I/O; preempting A [Q J B C H K M O]
time 51ms: Process J (tau 55ms) started using the CPU with 204ms burst remaining [Q A B C H K M O]
time 65ms: Process G (tau 100ms) arrived; added to ready queue [Q A B C G H K M O]
time 68ms: Process I (tau 100ms) arrived; added to ready queue [Q A B C G H I K M O]
time 106ms: Process F (tau 100ms) arrived; added to ready queue [Q A B C F G H I K M O]
time 122ms: Process N (tau 100ms) arrived; added to ready queue [Q A B C F G H I K M N O]
time 134ms: Process E (tau 100ms) arrived; added to ready queue [Q A B C E F G H I K M N O]
time 156ms: Process D (tau 100ms) arrived; added to ready queue [Q A B C D E F G H I K M N O]
time 159ms: Process P (tau 100ms) arrived; added to ready queue [Q A B C D E F G H I K M N O P]
time 189ms: Process L (tau 100ms) arrived; added to ready queue [Q A B C D E F G H I K L M N O P]
time 255ms: Process J (tau 55ms) completed a CPU burst; 8 bursts to go [Q A B C D E F G H I K L M N O P]
time 255ms: Recalculated tau = 167ms for process J [Q A B C D E F G H I K L M N O P]
time 255ms: Process J switching out of CPU; will block on I/O until time 327ms [Q A B C D E F G H I K L M N O P]
time 259ms: Process A (tau 100ms) started using the CPU with 55ms burst remaining [Q B C D E F G H I K L M N O P]
time 314ms: Process A (tau 100ms) completed a CPU burst; 15 bursts to go [Q B C D E F G H I K L M N O P]
time 314ms: Recalculated tau = 67ms for process A [Q B C D E F G H I K L M N O P]
time 314ms: Process A switching out of CPU; will block on I/O until time 339ms [Q B C D E F G H I K L M N O P]
time 318ms: Process B (tau 100ms) started using the CPU with 106ms burst remaining [Q C D E F G H I K L M N O P]
time 327ms: Process J (tau 167ms) completed I/O; added to ready queue [Q C D E F G H I K L M N O P J]
time 339ms: Process A (tau 67ms) completed I/O; preempting B [Q A C D E F G H I K L M N O P J]
time 343ms: Process A (tau 67ms) started using the CPU with 60ms burst remaining [Q B C D E F G H I K L M N O P J]
time 403ms: Process A (tau 67ms) completed a CPU burst; 14 bursts to go [Q B C D E F G H I K L M N O P J]
time 403ms: Recalculated tau = 62ms for process A [Q B C D E F G H I K L M N O P J]
time 403ms: Process A switching out of CPU; will block on I/O until time 558ms [Q B C D E F G H I K L M N O P J]
time 407ms: Process B (tau 100ms) started using the CPU with 85ms burst remaining [Q C D E F G H I K L M N O P J]
time 492ms: Process B (tau 100ms) completed a CPU burst; 20 bursts to go [Q C D E F G H I K L M N O P J]
time 492ms: Recalculated tau = 105ms for process B [Q C D E F G H I K L M N O P J]
time 492ms: Process B switching out of CPU; will block on I/O until time 650ms [Q C D E F G H I K L M N O P J]
time 496ms: Process C (tau 100ms) started using the CPU with 94ms burst remaining [Q D E F G H I K L M N O P J]
time 558ms: Process A (tau 62ms) completed I/O; added to ready queue [Q A D E F G H I K L M N O P J]
time 590ms: Process C (tau 100ms) completed a CPU burst; 3 bursts to go [Q A D E F G H I K L M N O P J]
time 590ms: Recalculated tau = 96ms for process C [Q A D E F G H I K L M N O P J]
time 590ms: Process C switching out of CPU; will block on I/O until time 750ms [Q A D E F G H I K L M N O P J]
time 594ms: Process A (tau 62ms) started using the CPU with 39ms burst remaining [Q D E F G H I K L M N O P J]
time 633ms: Process A (tau 62ms) completed a CPU burst; 13 bursts to go [Q D E F G H I K L M N O P J]
time 633ms: Recalculated tau = 45ms for process A [Q D E F G H I K L M N O P J]
time 633ms: Process A switching out of CPU; will block on I/O until time 685ms [Q D E F G H I K L M N O P J]
time 637ms: Process D (tau 100ms) started using the CPU with 148ms burst remaining [Q E F G H I K L M N O P J]
time 650ms: Process B (tau 105ms) completed I/O; added to ready queue [Q E F G H I K L M N O P B J]
time 685ms: Process A (tau 45ms) completed I/O; preempting D [Q A E F G H I K L M N O P B J]
time 689ms: Process A (tau 45ms) started using the CPU with 47ms burst remaining [Q D E F G H I K L M N O P B J]
time 736ms: Process A (tau 45ms) completed a CPU burst; 12 bursts to go [Q D E F G H I K L M N O P B J]
time 736ms: Recalculated tau = 47ms for process A [Q D E F G H I K L M N O P B J]
time 736ms: Process A switching out of CPU; will block on I/O until time 740ms [Q D E F G H I K L M N O P B J]
time 740ms: Process D (tau 100ms) started using the CPU with 100ms burst remaining [Q E F G H I K L M N O P B J]
time 740ms: Process A (tau 47ms) completed I/O; preempting D [Q A E F G H I K L M N O P B J]
time 744ms: Process A (tau 47ms) started using the CPU with 137ms burst remaining [Q D E F G H I K L M N O P B J]
time 750ms: Process C (tau 96ms) completed I/O; added to ready queue [Q D C E F G H I K L M N O P B J]
time 881ms: Process A (tau 47ms) completed a CPU burst; 11 bursts to go [Q D C E F G H I K L M N O P B J]
time 881ms: Recalculated tau = 115ms for process A [Q D C E F G H I K L M N O P B J]
time 881ms: Process A switching out of CPU; will block on I/O until time 907ms [Q D C E F G H I K L M N O P B J]
time 885ms: Process D (tau 100ms) started using the CPU with 100ms burst remaining [Q C E F G H I K L M N O P B J]
time 907ms: Process A (tau 115ms) completed I/O; added to ready queue [Q C E F G H I K L M N O P B A J]
time 985ms: Process D (tau 100ms) completed a CPU burst; 10 bursts to go [Q C E F G H I K L M N O P B A J]
time 985ms: Recalculated tau = 136ms for process D [Q C E F G H I K L M N O P B A J]
time 985ms: Process D switching out of CPU; will block on I/O until time 989ms [Q C E F G H I K L M N O P B A J]
time 989ms: Process C (tau 96ms) started using the CPU with 117ms burst remaining [Q E F G H I K L M N O P B A J]
time 989ms: Process D (tau 136ms) completed I/O; added to ready queue [Q E F G H I K L M N O P B A D J]
time 4756ms: Process C terminated [Q A K F L H P D E O M J B N I]
time 7167ms: Process L terminated [Q H A P D E O M G F J K B N I]
time 10826ms: Process A terminated [Q J E H P K B F N M I D]
time 17768ms: Process J terminated [Q K B P F N M I D O H E]
time 17982ms: Process K terminated [Q B P F N M I D O H E]
time 18855ms: Process P terminated [Q N M I D B O H E]
time 24829ms: Process D terminated [Q I F N M B O H E G]
time 26809ms: Process F terminated [Q I M B O H E G]
time 33671ms: Process O terminated [Q I H N B E G]
time 34092ms: Process M terminated [Q I H N B E G]
time 38109ms: Process B terminated [Q I N E G]
time 38956ms: Process N terminated [Q H E G]
time 44270ms: Process G terminated [Q I E]
time 46228ms: Process E terminated [Q H I]
time 48375ms: Process I terminated [Q <empty>]
time 48520ms: Process H terminated [Q <empty>]
time 48522ms: Simulator ended for SRT [Q <empty>]

Process A [NEW] (arrival time 9 ms) 16 CPU bursts
Process B [NEW] (arrival time 18 ms) 21 CPU bursts
Process C [NEW] (arrival time 42 ms) 4 CPU bursts
Process D [NEW] (arrival time 156 ms) 11 CPU bursts
Process E [NEW] (arrival time 134 ms) 55 CPU bursts
Process F [NEW] (arrival time 106 ms) 34 CPU bursts
Process G [NEW] (arrival time 65 ms) 80 CPU bursts
Process H [NEW] (arrival time 11 ms) 83 CPU bursts
Process I [NEW] (arrival time 68 ms) 77 CPU bursts
Process J [NEW] (arrival time 0 ms) 10 CPU bursts
Process K [NEW] (arrival time 7 ms) 13 CPU bursts
Process L [NEW] (arrival time 189 ms) 7 CPU bursts
Process M [NEW] (arrival time 16 ms) 48 CPU bursts
Process N [NEW] (arrival time 122 ms) 31 CPU bursts
Process O [NEW] (arrival time 29 ms) 31 CPU bursts
Process P [NEW] (arrival time 159 ms) 16 CPU bursts
time 0ms: Simulator started for RR [Q <empty>]
time 0ms: Process J arrived; added to ready queue [Q J]
time 2ms: Process J started using the CPU for 40ms burst [Q <empty>]
time 7ms: Process K arrived; added to ready queue [Q K]
time 9ms: Process A arrived; added to ready queue [Q K A]
time 11ms: Process H arrived; added to ready queue [Q K A H]
time 16ms: Process M arrived; added to ready queue [Q K A H M]
time 18ms: Process B arrived; added to ready queue [Q K A H M B]
time 29ms: Process O arrived; added to ready queue [Q K A H M B O]
time 42ms: Process J completed a CPU burst; 9 bursts to go [Q K A H M B O]
time 42ms: Process J switching out of CPU; will block on I/O until time 47ms [Q K A H M B O]
time 42ms: Process C arrived; added to ready queue [Q K A H M B O C]
time 46ms: Process K started using the CPU for 64ms burst [Q A H M B O C]
time 47ms: Process J completed I/O; added to ready queue [Q A H M B O C J]
time 65ms: Process G arrived; added to ready queue [Q A H M B O C J G]
time 68ms: Process I arrived; added to ready queue [Q A H M B O C J G I]
time 106ms: Process F arrived; added to ready queue [Q A H M B O C J G I F]
time 110ms: Process K completed a CPU burst; 12 bursts to go [Q A H M B O C J G I F]
time 110ms: Process K switching out of CPU; will block on I/O until time 208ms [Q A H M B O C J G I F]
time 114ms: Process A started using the CPU for 56ms burst [Q H M B O C J G I F]
time 122ms: Process N arrived; added to ready queue [Q H M B O C J G I F N]
time 134ms: Process E arrived; added to ready queue [Q H M B O C J G I F N E]
time 156ms: Process D arrived; added to ready queue [Q H M B O C J G I F N E D]
time 159ms: Process P arrived; added to ready queue [Q H M B O C J G I F N E D P]
time 170ms: Process A completed a CPU burst; 15 bursts to go [Q H M B O C J G I F N E D P]
time 170ms: Process A switching out of CPU; will block on I/O until time 195ms [Q H M B O C J G I F N E D P]
time 174ms: Process H started using the CPU for 96ms burst [Q M B O C J G I F N E D P]
time 189ms: Process L arrived; added to ready queue [Q M B O C J G I F N E D P L]
time 195ms: Process A completed I/O; added to ready queue [Q M B O C J G I F N E D P L A]
time 208ms: Process K completed I/O; added to ready queue [Q M B O C J G I F N E D P L A K]
time 238ms: Time slice expired; process H preempted with 32ms to go [Q M B O C J G I F N E D P L A K]
time 242ms: Process M started using the CPU for 22ms burst [Q B O C J G I F N E D P L A K H]
time 264ms: Process M completed a CPU burst; 47 bursts to go [Q B O C J G I F N E D P L A K H]
time 264ms: Process M switching out of CPU; will block on I/O until time 283ms [Q B O C J G I F N E D P L A K H]
time 268ms: Process B started using the CPU for 106ms burst [Q O C J G I F N E D P L A K H]
time 283ms: Process M completed I/O; added to ready queue [Q O C J G I F N E D P L A K H M]
time 332ms: Time slice expired; process B preempted with 42ms to go [Q O C J G I F N E D P L A K H M]
time 336ms: Process O started using the CPU for 156ms burst [Q C J G I F N E D P L A K H M B]
time 400ms: Time slice expired; process O preempted with 92ms to go [Q C J G I F N E D P L A K H M B]
time 404ms: Process C started using the CPU for 94ms burst [Q J G I F N E D P L A K H M B O]
time 468ms: Time slice expired; process C preempted with 30ms to go [Q J G I F N E D P L A K H M B O]
time 472ms: Process J started using the CPU for 204ms burst [Q G I F N E D P L A K H M B O C]
time 536ms: Time slice expired; process J preempted with 140ms to go [Q G I F N E D P L A K H M B O C]
time 540ms: Process G started using the CPU for 70ms burst [Q I F N E D P L A K H M B O C J]
time 604ms: Time slice expired; process G preempted with 6ms to go [Q I F N E D P L A K H M B O C J]
time 608ms: Process I started using the CPU for 220ms burst [Q F N E D P L A K H M B O C J G]
time 672ms: Time slice expired; process I preempted with 156ms to go [Q F N E D P L A K H M B O C J G]
time 676ms: Process F started using the CPU for 129ms burst [Q N E D P L A K H M B O C J G I]
time 740ms: Time slice expired; process F preempted with 65ms to go [Q N E D P L A K H M B O C J G I]
time 744ms: Process N started using the CPU for 213ms burst [Q E D P L A K H M B O C J G I F]
time 808ms: Time slice expired; process N preempted with 149ms to go [Q E D P L A K H M B O C J G I F]
time 812ms: Process E started using the CPU for 152ms burst [Q D P L A K H M B O C J G I F N]
time 876ms: Time slice expired; process E preempted with 88ms to go [Q D P L A K H M B O C J G I F N]
time 880ms: Process D started using the CPU for 148ms burst [Q P L A K H M B O C J G I F N E]
time 944ms: Time slice expired; process D preempted with 84ms to go [Q P L A K H M B O C J G I F N E]
time 948ms: Process P started using the CPU for 4ms burst [Q L A K H M B O C J G I F N E D]
time 952ms: Process P completed a CPU burst; 15 bursts to go [Q L A K H M B O C J G I F N E D]
time 952ms: Process P switching out of CPU; will block on I/O until time 1139ms [Q L A K H M B O C J G I F N E D]
time 956ms: Process L started using the CPU for 135ms burst [Q A K H M B O C J G I F N E D]
time 5900ms: Process C terminated [Q M I F O N E A K D H L B]
time 9632ms: Process L terminated [Q A H K F J P B M O D G I E N]
time 11172ms: Process J terminated [Q B M P N O D I E G H A]
time 13425ms: Process D terminated [Q H G P E K A F N B I O]
time 14159ms: Process K terminated [Q E F A N B I O H M P G]
time 17774ms: Process A terminated [Q P O I G E F H B]
time 19500ms: Process P terminated [Q N E O M I G F H B]
time 28099ms: Process B terminated [Q O I H G M F N]
time 31432ms: Process O terminated [Q N F G I M H E]
time 33308ms: Process N terminated [Q I G H F E M]
time 34298ms: Process F terminated [Q E M I H G]
time 40444ms: Process M terminated [Q H G I E]
time 42099ms: Process E terminated [Q H]
time 48189ms: Process G terminated [Q I]
time 49496ms: Process I terminated [Q H]
time 49529ms: Process H terminated [Q <empty>]
time 49531ms: Simulator ended for RR [Q <empty>]
